<?xml version="1.0" encoding="utf-8"?>
<!-- This URDF was automatically created by SolidWorks to URDF Exporter! Originally created by Stephen Brawner (brawner@gmail.com) 
     Commit Version: 1.5.1-0-g916b5db  Build Version: 1.5.7152.31018
     For more information, please see http://wiki.ros.org/sw_urdf_exporter -->
<robot
  name="Smart Bikeurdf">
  <link
    name="base_link">
    <inertial>
      <origin
        xyz="0.0722414458772001 -0.000329243736184398 0.0656471639885814"
        rpy="0 0 0" />
      <mass
        value="26.5006139612952" />
      <inertia
        ixx="0.5782842540228"
        ixy="-0.000298457705491019"
        ixz="-0.377965754513271"
        iyy="1.38147821949733"
        iyz="-0.00109915467822593"
        izz="0.879835771689076" />
    </inertial>
    <visual>
      <origin
        xyz="0 0 0"
        rpy="0 0 0" />
      <geometry>
        <mesh
          filename="package://Smart Bikeurdf/meshes/base_link.STL" />
      </geometry>
      <material
        name="">
        <color
          rgba="0.941176470588235 0 0.250980392156863 1" />
      </material>
    </visual>
    <collision>
      <origin
        xyz="0 0 0"
        rpy="0 0 0" />
      <geometry>
        <mesh
          filename="package://Smart Bikeurdf/meshes/base_link.STL" />
      </geometry>
    </collision>
  </link>
  <link
    name="steer_Link">
    <inertial>
      <origin
        xyz="0.0234035698400135 -1.05448629272864E-08 -0.132728241539369"
        rpy="0 0 0" />
      <mass
        value="0.186571576321353" />
      <inertia
        ixx="0.00145855716708279"
        ixy="9.34710119970269E-12"
        ixz="0.000188998536330559"
        iyy="0.00111447720678665"
        iyz="3.63880667686322E-12"
        izz="0.000420018698932838" />
    </inertial>
    <visual>
      <origin
        xyz="0 0 0"
        rpy="0 0 0" />
      <geometry>
        <mesh
          filename="package://Smart Bikeurdf/meshes/steer_Link.STL" />
      </geometry>
      <material
        name="">
        <color
          rgba="0.988235294117647 1 0.317647058823529 1" />
      </material>
    </visual>
    <collision>
      <origin
        xyz="0 0 0"
        rpy="0 0 0" />
      <geometry>
        <mesh
          filename="package://Smart Bikeurdf/meshes/steer_Link.STL" />
      </geometry>
    </collision>
  </link>
  <joint
    name="steer2base"
    type="continuous">
    <origin
      xyz="0.41186 0 0.12304"
      rpy="0 0 0" />
    <parent
      link="base_link" />
    <child
      link="steer_Link" />
    <axis
      xyz="-0.17365 0 0.98481" />
  </joint>
  <link
    name="front_tire_Link">
    <inertial>
      <origin
        xyz="0.116080376042657 0.0593890353143178 -2.77555756156289E-17"
        rpy="0 0 0" />
      <mass
        value="4.97972144336047" />
      <inertia
        ixx="0.0810473741653513"
        ixy="2.4024113138658E-18"
        ixz="2.19519963152342E-18"
        iyy="0.0810473741653513"
        iyz="-1.13834569034468E-17"
        izz="0.147017888395435" />
    </inertial>
    <visual>
      <origin
        xyz="0 0 0"
        rpy="0 0 0" />
      <geometry>
        <mesh
          filename="package://Smart Bikeurdf/meshes/front_tire_Link.STL" />
      </geometry>
      <material
        name="">
        <color
          rgba="0.898039215686275 0.92156862745098 0.929411764705882 1" />
      </material>
    </visual>
    <collision>
      <origin
        xyz="0 0 0"
        rpy="0 0 0" />
      <geometry>
        <mesh
          filename="package://Smart Bikeurdf/meshes/front_tire_Link.STL" />
      </geometry>
    </collision>
  </link>
  <joint
    name="ft2steer"
    type="continuous">
    <origin
      xyz="0.048144 0 -0.27304"
      rpy="1.5625 0 0.046962" />
    <parent
      link="steer_Link" />
    <child
      link="front_tire_Link" />
    <axis
      xyz="0 0 1" />
  </joint>
  <link
    name="back_tire_Link">
    <inertial>
      <origin
        xyz="0 0 0"
        rpy="0 0 0" />
      <mass
        value="0.57295" />
      <inertia
        ixx="0.0032221"
        ixy="5.915E-35"
        ixz="4.5091E-19"
        iyy="0.0032221"
        iyz="6.0704E-36"
        izz="0.0063501" />
    </inertial>
    <visual>
      <origin
        xyz="0 0 0"
        rpy="0 0 0" />
      <geometry>
        <mesh
          filename="package://Smart Bikeurdf/meshes/back_tire_Link.STL" />
      </geometry>
      <material
        name="">
        <color
          rgba="0 0 0 1" />
      </material>
    </visual>
    <collision>
      <origin
        xyz="0 0 0"
        rpy="0 0 0" />
      <geometry>
        <mesh
          filename="package://Smart Bikeurdf/meshes/back_tire_Link.STL" />
      </geometry>
    </collision>
  </link>
  <joint
    name="bt2base"
    type="continuous">
    <origin
      xyz="-0.32 0 -0.15"
      rpy="1.5708 0 0" />
    <parent
      link="base_link" />
    <child
      link="back_tire_Link" />
    <axis
      xyz="0 0 1" />
  </joint>
  <link
    name="left_hip_Link">
    <inertial>
      <origin
        xyz="-0.00555726936318846 -0.00054746202116468 5.80578443659663E-06"
        rpy="0 0 0" />
      <mass
        value="0.127394275254527" />
      <inertia
        ixx="5.65233830449628E-05"
        ixy="1.16592738397559E-06"
        ixz="-1.21707423162195E-07"
        iyy="0.000106228884116206"
        iyz="1.22498446949969E-08"
        izz="5.83671022291641E-05" />
    </inertial>
    <visual>
      <origin
        xyz="0 0 0"
        rpy="0 0 0" />
      <geometry>
        <mesh
          filename="package://Smart Bikeurdf/meshes/left_hip_Link.STL" />
      </geometry>
      <material
        name="">
        <color
          rgba="0.752941176470588 0.752941176470588 0.752941176470588 1" />
      </material>
    </visual>
    <collision>
      <origin
        xyz="0 0 0"
        rpy="0 0 0" />
      <geometry>
        <mesh
          filename="package://Smart Bikeurdf/meshes/left_hip_Link.STL" />
      </geometry>
    </collision>
  </link>
  <joint
    name="lh2base"
    type="continuous">
    <origin
      xyz="0.0618 0.05 -0.037"
      rpy="0 0 0" />
    <parent
      link="base_link" />
    <child
      link="left_hip_Link" />
    <axis
      xyz="1 0 0" />
  </joint>
  <link
    name="left_thigh_Link">
    <inertial>
      <origin
        xyz="0.00158569560315369 -0.0229276842254627 -0.00517798748431686"
        rpy="0 0 0" />
      <mass
        value="0.17662112342636" />
      <inertia
        ixx="8.87397408843006E-05"
        ixy="-1.24465518708638E-06"
        ixz="-1.22396707123807E-07"
        iyy="0.000154391888360348"
        iyz="1.97467514560804E-06"
        izz="7.99950561198151E-05" />
    </inertial>
    <visual>
      <origin
        xyz="0 0 0"
        rpy="0 0 0" />
      <geometry>
        <mesh
          filename="package://Smart Bikeurdf/meshes/left_thigh_Link.STL" />
      </geometry>
      <material
        name="">
        <color
          rgba="0.752941176470588 0.752941176470588 0.752941176470588 1" />
      </material>
    </visual>
    <collision>
      <origin
        xyz="0 0 0"
        rpy="0 0 0" />
      <geometry>
        <mesh
          filename="package://Smart Bikeurdf/meshes/left_thigh_Link.STL" />
      </geometry>
    </collision>
  </link>
  <joint
    name="lt2lh"
    type="continuous">
    <origin
      xyz="0 0.0755 0"
      rpy="0 0 0" />
    <parent
      link="left_hip_Link" />
    <child
      link="left_thigh_Link" />
    <axis
      xyz="0 1 0" />
  </joint>
  <link
    name="left_shank_Link">
    <inertial>
      <origin
        xyz="3.33494609954244E-05 0.000114931303107996 -0.0865263868698282"
        rpy="0 0 0" />
      <mass
        value="0.0467421397469521" />
      <inertia
        ixx="4.72408440400434E-05"
        ixy="-3.28107474647144E-12"
        ixz="4.62861079304687E-08"
        iyy="4.9362568902293E-05"
        iyz="2.33953161815665E-11"
        izz="8.85160898810831E-06" />
    </inertial>
    <visual>
      <origin
        xyz="0 0 0"
        rpy="0 0 0" />
      <geometry>
        <mesh
          filename="package://Smart Bikeurdf/meshes/left_shank_Link.STL" />
      </geometry>
      <material
        name="">
        <color
          rgba="0.752941176470588 0.752941176470588 0.752941176470588 1" />
      </material>
    </visual>
    <collision>
      <origin
        xyz="0 0 0"
        rpy="0 0 0" />
      <geometry>
        <mesh
          filename="package://Smart Bikeurdf/meshes/left_shank_Link.STL" />
      </geometry>
    </collision>
  </link>
  <joint
    name="ls2lt"
    type="continuous">
    <origin
      xyz="0 0 -0.2115"
      rpy="0 0 0" />
    <parent
      link="left_thigh_Link" />
    <child
      link="left_shank_Link" />
    <axis
      xyz="0 1 0" />
  </joint>
  <link
    name="right_hip_Link">
    <inertial>
      <origin
        xyz="0 0 0"
        rpy="0 0 0" />
      <mass
        value="0" />
      <inertia
        ixx="0"
        ixy="0"
        ixz="0"
        iyy="0"
        iyz="0"
        izz="0" />
    </inertial>
    <visual>
      <origin
        xyz="0 0 0"
        rpy="0 0 0" />
      <geometry>
        <mesh
          filename="package://Smart Bikeurdf/meshes/right_hip_Link.STL" />
      </geometry>
      <material
        name="">
        <color
          rgba="1 1 1 1" />
      </material>
    </visual>
    <collision>
      <origin
        xyz="0 0 0"
        rpy="0 0 0" />
      <geometry>
        <mesh
          filename="package://Smart Bikeurdf/meshes/right_hip_Link.STL" />
      </geometry>
    </collision>
  </link>
  <joint
    name="rh2base"
    type="continuous">
    <origin
      xyz="0.0618 -0.05 -0.037"
      rpy="0 0 0" />
    <parent
      link="base_link" />
    <child
      link="right_hip_Link" />
    <axis
      xyz="1 0 0" />
  </joint>
  <link
    name="right_thigh_Link">
    <inertial>
      <origin
        xyz="-0.00158569353946758 0.0229276866213309 -0.00517798853200702"
        rpy="0 0 0" />
      <mass
        value="0.176621137371715" />
      <inertia
        ixx="8.87397458283353E-05"
        ixy="-1.24465369797289E-06"
        ixz="1.22401164415761E-07"
        iyy="0.000154391897488737"
        iyz="-1.9746749094057E-06"
        izz="7.99950602069772E-05" />
    </inertial>
    <visual>
      <origin
        xyz="0 0 0"
        rpy="0 0 0" />
      <geometry>
        <mesh
          filename="package://Smart Bikeurdf/meshes/right_thigh_Link.STL" />
      </geometry>
      <material
        name="">
        <color
          rgba="0.752941176470588 0.752941176470588 0.752941176470588 1" />
      </material>
    </visual>
    <collision>
      <origin
        xyz="0 0 0"
        rpy="0 0 0" />
      <geometry>
        <mesh
          filename="package://Smart Bikeurdf/meshes/right_thigh_Link.STL" />
      </geometry>
    </collision>
  </link>
  <joint
    name="rt2rh"
    type="continuous">
    <origin
      xyz="0 -0.0755 0"
      rpy="0 0 0" />
    <parent
      link="right_hip_Link" />
    <child
      link="right_thigh_Link" />
    <axis
      xyz="0 -1 0" />
  </joint>
  <link
    name="right_shank_Link">
    <inertial>
      <origin
        xyz="-3.33494612840823E-05 -0.000114931302212573 -0.0865263868693705"
        rpy="0 0 0" />
      <mass
        value="0.0467421397478625" />
      <inertia
        ixx="4.7240844040754E-05"
        ixy="-3.22594158067212E-12"
        ixz="-4.62861066862666E-08"
        iyy="4.93625689029303E-05"
        iyz="-2.33942211044382E-11"
        izz="8.8516089881699E-06" />
    </inertial>
    <visual>
      <origin
        xyz="0 0 0"
        rpy="0 0 0" />
      <geometry>
        <mesh
          filename="package://Smart Bikeurdf/meshes/right_shank_Link.STL" />
      </geometry>
      <material
        name="">
        <color
          rgba="0.752941176470588 0.752941176470588 0.752941176470588 1" />
      </material>
    </visual>
    <collision>
      <origin
        xyz="0 0 0"
        rpy="0 0 0" />
      <geometry>
        <mesh
          filename="package://Smart Bikeurdf/meshes/right_shank_Link.STL" />
      </geometry>
    </collision>
  </link>
  <joint
    name="rs2rt"
    type="continuous">
    <origin
      xyz="0 0 -0.2115"
      rpy="0 0 0" />
    <parent
      link="right_thigh_Link" />
    <child
      link="right_shank_Link" />
    <axis
      xyz="0 -1 0" />
  </joint>
</robot>