<?xml version="1.0" encoding="utf-8"?>
<!-- This URDF was automatically created by SolidWorks to URDF Exporter! Originally created by Stephen Brawner (brawner@gmail.com) 
     Commit Version: 1.5.1-0-g916b5db  Build Version: 1.5.7152.31018
     For more information, please see http://wiki.ros.org/sw_urdf_exporter -->
<robot
  name="licycle">
  <link
    name="base_link">
    <inertial>
      <origin
        xyz="-0.17667 1.3393E-06 0.049412"
        rpy="0 0 0" />
      <mass
        value="10.984" />
      <inertia
        ixx="0.20845"
        ixy="-1.3056E-06"
        ixz="-0.10336"
        iyy="0.49031"
        iyz="1.072E-06"
        izz="0.33222" />
    </inertial>
    <visual>
      <origin
        xyz="0 0 0"
        rpy="0 0 0" />
      <geometry>
        <mesh
          filename="../meshes/base_link.obj" />
      </geometry>
      <material
        name="">
        <color
          rgba="0.2 0.2 0.2 1" />
      </material>
    </visual>
    <collision>
      <origin
        xyz="0 0 0"
        rpy="0 0 0" />
      <geometry>
        <mesh
          filename="../meshes/base_link.obj" />
      </geometry>
    </collision>
  </link>
  <link
    name="steer_Link">
    <inertial>
      <origin
        xyz="-0.0077245 -4.0635E-06 0.17007"
        rpy="0 0 0" />
      <mass
        value="2.9093" />
      <inertia
        ixx="0.16648"
        ixy="7.5482E-07"
        ixz="0.013784"
        iyy="0.13395"
        iyz="-4.8807E-06"
        izz="0.040758" />
    </inertial>
    <visual>
      <origin
        xyz="0 0 0"
        rpy="0 0 0" />
      <geometry>
        <mesh
          filename="../meshes/steer_Link.obj" />
      </geometry>
      <material
        name="">
        <color
          rgba="0.2 0.2 0.2 1" />
      </material>
    </visual>
    <collision>
      <origin
        xyz="0 0 0"
        rpy="0 0 0" />
      <geometry>
        <mesh
          filename="../meshes/steer_Link.obj" />
      </geometry>
    </collision>
  </link>
  <joint
    name="steer2base"
    type="continuous">
    <origin
      xyz="0.37689 0 0.099076"
      rpy="0 0 0" />
    <parent
      link="base_link" />
    <child
      link="steer_Link" />
    <axis
      xyz="0.29237 0 -0.9563" />
  </joint>
  <link
    name="front_tire_Link">
    <inertial>
      <origin
        xyz="-1.1102E-16 -3.4641E-18 -2.7756E-17"
        rpy="0 0 0" />
      <mass
        value="4.7835" />
      <inertia
        ixx="0.042889"
        ixy="-2.505E-19"
        ixz="4.8667E-19"
        iyy="0.081184"
        iyz="-3.105E-20"
        izz="0.042889" />
    </inertial>
    <visual>
      <origin
        xyz="0 0 0"
        rpy="0 0 0" />
      <geometry>
        <mesh
          filename="../meshes/front_tire_Link.obj" />
      </geometry>
      <material
        name="">
        <color
          rgba="1 1 1 1" />
      </material>
    </visual>
    <collision>
      <origin
        xyz="0 0 0"
        rpy="0 0 0" />
      <geometry>
        <mesh
          filename="../meshes/front_tire_Link.obj" />
      </geometry>
      <material name="">
        <contact name="rubber"/>
      </material>
    </collision>
  </link>
  <joint
    name="ft2steer"
    type="continuous">
    <origin
      xyz="0.0730929261806841 0 -0.239076188990759"
      rpy="0 0 0" />
    <parent
      link="steer_Link" />
    <child
      link="front_tire_Link" />
    <axis
      xyz="0 -1 0" />
  </joint>
  <link
    name="back_tire_Link">
    <inertial>
      <origin
        xyz="-5.5722E-18 2.1181E-18 0"
        rpy="0 0 0" />
      <mass
        value="1.9195" />
      <inertia
        ixx="0.033227"
        ixy="3.146E-35"
        ixz="3.3149E-34"
        iyy="0.06574"
        iyz="0"
        izz="0.033227" />
    </inertial>
    <visual>
      <origin
        xyz="0 0 0"
        rpy="0 0 0" />
      <geometry>
        <mesh
          filename="../meshes/back_tire_Link.obj" />
      </geometry>
      <material
        name="">
        <color
          rgba="1 1 1 1" />
      </material>
    </visual>
    <collision>
      <origin
        xyz="0 0 0"
        rpy="0 0 0" />
      <geometry>
        <mesh
          filename="../meshes/back_tire_Link.obj" />
      </geometry>
      <material name="">
        <contact name="rubber"/>
      </material>
    </collision>
  </link>
  <joint
    name="bt2base"
    type="continuous">
    <origin
      xyz="-0.42 0 -0.145"
      rpy="0 0 0" />
    <parent
      link="base_link" />
    <child
      link="back_tire_Link" />
    <axis
      xyz="0 1 0" />
  </joint>
  <link
    name="left_hip_Link">
    <inertial>
      <origin
        xyz="-0.0055366 -0.00054746 -0.00047856"
        rpy="0 0 0" />
      <mass
        value="0.5" />
      <inertia
        ixx="0.000"
        ixy="0.000"
        ixz="0.000"
        iyy="0.000"
        iyz="0.000"
        izz="0.000" />
    </inertial>
    <visual>
      <origin
        xyz="0 0 0"
        rpy="0 0 0" />
      <geometry>
        <mesh
          filename="../meshes/left_hip_Link.obj" />
      </geometry>
      <material
        name="">
        <color
          rgba="0.75294 0.75294 0.75294 1" />
      </material>
    </visual>
    <collision>
      <origin
        xyz="0 0 0"
        rpy="0 0 0" />
      <geometry>
        <mesh
          filename="../meshes/left_hip_Link.obj" />
      </geometry>
    </collision>
  </link>
  <joint
    name="lh2base"
    type="continuous">
    <origin
      xyz="-0.02599 0.13025 -0.044158"
      rpy="0 0 0" />
    <parent
      link="base_link" />
    <child
      link="left_hip_Link" />
    <axis
      xyz="0.99619 0 0.087156" />
  </joint>
  <link
    name="left_thigh_Link">
    <inertial>
      <origin
        xyz="0.0020309 -0.022928 -0.0050201"
        rpy="0 0 0" />
      <mass
        value="0.65" />
      <inertia
        ixx="0.001"
        ixy="0.000"
        ixz="0.000"
        iyy="0.001"
        iyz="0.000"
        izz="0.000" />
    </inertial>
    <visual>
      <origin
        xyz="0 0 0"
        rpy="0 0 0" />
      <geometry>
        <mesh
          filename="../meshes/left_thigh_Link.obj" />
      </geometry>
      <material
        name="">
        <color
          rgba="0.75294 0.75294 0.75294 1" />
      </material>
    </visual>
    <collision>
      <origin
        xyz="0 0 0"
        rpy="0 0 0" />
      <geometry>
        <mesh
          filename="../meshes/left_thigh_Link.obj" />
      </geometry>
    </collision>
  </link>
  <joint
    name="lt2lh"
    type="continuous">
    <origin
      xyz="0 0.0755000295197773 0"
      rpy="0 0 0" />
    <parent
      link="left_hip_Link" />
    <child
      link="left_thigh_Link" />
    <axis
      xyz="0 -0.999999999999975 0" />
  </joint>
  <link
    name="left_shank_Link">
    <inertial>
      <origin
        xyz="0.007508 -0.00011487 -0.0862"
        rpy="0 0 0" />
      <mass
        value="0.2" />
      <inertia
        ixx="0.002"
        ixy="0.000"
        ixz="0.000"
        iyy="0.002"
        iyz="0.000"
        izz="0.000" />
    </inertial>
    <visual>
      <origin
        xyz="0 0 0"
        rpy="0 0 0" />
      <geometry>
        <mesh
          filename="../meshes/left_shank_Link.obj" />
      </geometry>
      <material
        name="">
        <color
          rgba="0.75294 0.75294 0.75294 1" />
      </material>
    </visual>
    <collision>
      <origin
        xyz="0 0 0"
        rpy="0 0 0" />
      <geometry>
        <mesh
          filename="../meshes/left_shank_Link.obj" />
      </geometry>
    </collision>
  </link>
  <joint
    name="ls2lt"
    type="continuous">
    <origin
      xyz="0.0184334391676658 0 -0.210695173786874"
      rpy="0 0 0" />
    <parent
      link="left_thigh_Link" />
    <child
      link="left_shank_Link" />
    <axis
      xyz="0 -0.999999999999975 0" />
  </joint>
  <link
    name="right_hip_Link">
    <inertial>
      <origin
        xyz="0 0 0"
        rpy="0 0 0" />
      <mass
        value="0.5" />
      <inertia
        ixx="0.000"
        ixy="0.000"
        ixz="0.000"
        iyy="0.000"
        iyz="0.000"
        izz="0.000" />
    </inertial>
    <visual>
      <origin
        xyz="0 0 0"
        rpy="0 0 0" />
      <geometry>
        <mesh
          filename="../meshes/right_hip_Link.obj" />
      </geometry>
      <material
        name="">
        <color
          rgba="1 1 1 1" />
      </material>
    </visual>
    <collision>
      <origin
        xyz="0 0 0"
        rpy="0 0 0" />
      <geometry>
        <mesh
          filename="../meshes/right_hip_Link.obj" />
      </geometry>
    </collision>
  </link>
  <joint
    name="rh2base"
    type="continuous">
    <origin
      xyz="-0.0259902129417648 -0.130249964154169 -0.0441582168729666"
      rpy="0 0 0" />
    <parent
      link="base_link" />
    <child
      link="right_hip_Link" />
    <axis
      xyz="0.996194698091746 0 0.087155742747658" />
  </joint>
  <link
    name="right_thigh_Link">
    <inertial>
      <origin
        xyz="-0.0011284 0.022928 -0.0052965"
        rpy="0 0 0" />
      <mass
        value="0.65" />
      <inertia
        ixx="0.001"
        ixy="0.000"
        ixz="0.000"
        iyy="0.001"
        iyz="0.000"
        izz="0.000" />
    </inertial>
    <visual>
      <origin
        xyz="0 0 0"
        rpy="0 0 0" />
      <geometry>
        <mesh
          filename="../meshes/right_thigh_Link.obj" />
      </geometry>
      <material
        name="">
        <color
          rgba="0.75294 0.75294 0.75294 1" />
      </material>
    </visual>
    <collision>
      <origin
        xyz="0 0 0"
        rpy="0 0 0" />
      <geometry>
        <mesh
          filename="../meshes/right_thigh_Link.obj" />
      </geometry>
    </collision>
  </link>
  <joint
    name="rt2rh"
    type="continuous">
    <origin
      xyz="0 -0.075500029519776 0"
      rpy="0 0 0" />
    <parent
      link="right_hip_Link" />
    <child
      link="right_thigh_Link" />
    <axis
      xyz="0 -0.99999999999995 0" />
  </joint>
  <link
    name="right_shank_Link">
    <inertial>
      <origin
        xyz="0.0075745 0.00011487 -0.086194"
        rpy="0 0 0" />
      <mass
        value="0.2" />
      <inertia
        ixx="0.002"
        ixy="0.000"
        ixz="0.000"
        iyy="0.002"
        iyz="0.000"
        izz="0.000" />
    </inertial>
    <visual>
      <origin
        xyz="0 0 0"
        rpy="0 0 0" />
      <geometry>
        <mesh
          filename="../meshes/right_shank_Link.obj" />
      </geometry>
      <material
        name="">
        <color
          rgba="0.75294 0.75294 0.75294 1" />
      </material>
    </visual>
    <collision>
      <origin
        xyz="0 0 0"
        rpy="0 0 0" />
      <geometry>
        <mesh
          filename="../meshes/right_shank_Link.obj" />
      </geometry>
    </collision>
  </link>
  <joint
    name="rs2rt"
    type="continuous">
    <origin
      xyz="0.0184334391643117 0 -0.210695173787168"
      rpy="0 0 0" />
    <parent
      link="right_thigh_Link" />
    <child
      link="right_shank_Link" />
    <axis
      xyz="0 -0.99999999999995 0" />
  </joint>
</robot>